Workbook

Sheet Sistema
A1: DATA | B1: DIA | C1: TURNO | D1: ESTÚDIO | E1: CANAL | F1: CURSO | G1: HORÁRIO | H1: DISCIPLINA | I1: PROFESSOR | J1: REGULAR | K1: SUBSTITUIÇÃO DE PROFESSOR | L1: PROFESSOR QUE SUBSTITUIU | M1: INTERAÇÃO PROFESSOR ALUNO | N1: TIPO DE INTERAÇÃO | O1: ATIVIDADE PRÁTICA PARA ESCOLA | P1: TIPO DE ATIVIDADE PRÁTICA | Q1: ATRASO PARA INÍCIO | R1: TEMPO DE ATRASO | S1: OBSERVAÇÃO ATRASO | T1: PROBLEMA COM MATERIAL | U1: MOTIVO DO PROBLEMA | V1: UTILIZOU ALGUM RECURSO | W1: TIPO DE RECURSO
A2: 13/03/2026 | B2: Sexta | C2: Noite | D2: Estúdio 04 | E2: Canal SEDUC PI 4 | F2: 3ª SÉRIE - NOITE | G2: 4º Horário | H2: APROFUNDAMENTO DA APRENDIZAGEM (LÍNGUA PORTUGUESA) | I2: Marilia Ferreira Mendes Vieira | J2: sim | K2: Não | L2: - | M2: Sim | N2: Chat | O2: Sim | P2: Exercício teórico | Q2: não | R2: não | T2: Sim | U2: Não | V2: Sim | W2: Slide
A3: 13/03/2026 | B3: Sexta | C3: Noite | D3: Estúdio 04 | E3: Canal SEDUC PI 4 | F3: 3ª SÉRIE - NOITE | G3: 3º Horário | H3: QUÍMICA | I3: Erica Ramos do Nascimento | J3: sim | K3: Não | L3: - | M3: Sim | N3: Chat | O3: Sim | P3: Exercício teórico | Q3: não | R3: não | T3: Sim | U3: Não | V3: Sim | W3: Slide
A4: 13/03/2026 | B4: Sexta | C4: Noite | D4: Estúdio 04 | E4: Canal SEDUC PI 4 | F4: 3ª SÉRIE - NOITE | G4: 2º Horário | H4: LÍNGUA PORTUGUESA - ANÁLISE LINGUÍSTICA | I4: Marilia Ferreira Mendes Vieira | J4: sim | K4: Não | L4: - | M4: Sim | N4: Chat | O4: Sim | P4: Exercício teórico | Q4: não | R4: não | T4: Sim | U4: Não | V4: Sim | W4: Slide
A5: 13/03/2026 | B5: Sexta | C5: Noite | D5: Estúdio 04 | E5: Canal SEDUC PI 4 | F5: 3ª SÉRIE - NOITE | G5: 1º Horário | H5: FILOSOFIA/SOCIOLOGIA (INTERDISCIPLINAR) | I5: Marciano de Brito | J5: sim | K5: Não | L5: - | M5: Sim | N5: Chat | O5: Sim | P5: Exercício teórico | Q5: não | R5: não | T5: Sim | U5: Não | V5: Sim | W5: Slide
A6: 13/03/2026 | B6: Sexta | C6: Noite | D6: Estúdio 03 | E6: Canal SEDUC PI 2 | F6: 2ª SÉRIE - NOITE | G6: 4º Horário | H6: AQUISIÇÃO DE CLIENTES | I6: Amanda Souza | J6: sim | K6: Não | L6: - | M6: Sim | N6: Chat | O6: Sim | P6: Exercício teórico | Q6: não | R6: não | T6: Sim | U6: Não | V6: Sim | W6: Slide
A7: 13/03/2026 | B7: Sexta | C7: Noite | D7: Estúdio 03 | E7: Canal SEDUC PI 2 | F7: 2ª SÉRIE - NOITE | G7: 3º Horário | H7: QUÍMICA | I7: Alcides Fernandes | J7: sim | K7: Não | L7: - | M7: Sim | N7: Chat | O7: Sim | P7: Exercício teórico | Q7: não | R7: não | T7: Sim | U7: Não | V7: Sim | W7: Slide
A8: 13/03/2026 | B8: Sexta | C8: Noite | D8: Estúdio 03 | E8: Canal SEDUC PI 2 | F8: 2ª SÉRIE - NOITE | G8: 2º Horário | H8: MODELO DE NEGÓCIOS INOVADORES | I8: Rildo Oliveira | J8: sim | K8: Não | L8: - | M8: Sim | N8: Chat | O8: Sim | P8: Exercício teórico | Q8: não | R8: não | T8: Sim | U8: Não | V8: Sim | W8: Slide
A9: 13/03/2026 | B9: Sexta | C9: Noite | D9: Estúdio 03 | E9: Canal SEDUC PI 2 | F9: 2ª SÉRIE - NOITE | G9: 1º Horário | H9: PROJETO DE VIDA | I9: Hamanda Soares Viana Pereira da Silva | J9: sim | K9: Não | L9: - | M9: Sim | N9: Chat | O9: Sim | P9: Exercício teórico | Q9: não | R9: não | T9: Sim | U9: Não | V9: Sim | W9: Slide
A10: 13/03/2026 | B10: Sexta | C10: Noite | D10: Estúdio 09 | E10: Gravação de aula estúdio | F10: 1ª SÉRIE - NOITE | G10: 5º Horário | H10: TEC. E MÉTODOS APRENDIZAGEM | I10: Amanda Souza | J10: sim | K10: Não | L10: - | M10: Sim | N10: Não | O10: Sim | P10: Exercício teórico | Q10: não | R10: não | T10: Sim | U10: Não | V10: Sim | W10: Slide
A11: 13/03/2026 | B11: Sexta | C11: Noite | D11: Estúdio 09 | E11: Canal SEDUC PI 1 | F11: 1ª SÉRIE - NOITE | G11: 3º Horário | H11: PROJETO DE VIDA | I11: Hamanda Soares Viana Pereira da Silva | J11: sim | K11: Não | L11: - | M11: Sim | N11: Chat | O11: Sim | P11: Exercício teórico | Q11: não | R11: não | T11: Sim | U11: Não | V11: Sim | W11: Slide
A12: 13/03/2026 | B12: Sexta | C12: Noite | D12: Estúdio 09 | E12: Canal SEDUC PI 1 | F12: 1ª SÉRIE - NOITE | G12: 2º Horário | H12: HISTÓRIA | I12: Flávio de Oliveira Coêlho Silva | J12: sim | K12: Não | L12: - | M12: Sim | N12: Chat | O12: Sim | P12: Exercício teórico | Q12: não | R12: não | T12: Sim | U12: Não | V12: Sim | W12: Slide
A13: 13/03/2026 | B13: Sexta | C13: Noite | D13: Estúdio 09 | E13: Canal SEDUC PI 1 | F13: 1ª SÉRIE - NOITE | G13: 1º Horário | H13: LÍNGUA PORTUGUESA - ANÁLISE LINGUÍSTICA | I13: Marilia Ferreira Mendes Vieira | J13: sim | K13: Não | L13: - | M13: Sim | N13: Chat | O13: Sim | P13: Exercício teórico | Q13: não | R13: não | T13: Sim | U13: Não | V13: Sim | W13: Slide
... A53: 13/03/2026 | B53: Sexta | C53: Manhã | D53: Estúdio 02 | E53: Canal SEDUC PI 2 | F53: 2ª SÉRIE INTEGRAL | G53: 1º Horário | H53: BIOLOGIA | I53: Assis Gualter Azevedo Neto | J53: sim | K53: Não | L53: - | M53: Sim | N53: Chat | O53: Sim | P53: Exercício teórico | Q53: não | R53: não | T53: Sim | U53: Não | V53: Sim | W53: Slide

Sheet Programacao
A1: DATA | B1: Dia da semana | C1: TURNO | D1: INICIO | E1: TERMINO | F1: ESTÚDIO | G1: Diretor de Imagem | H1: Disciplina | I1: Modalidade | J1: Canal IP.TV | K1: PROFESSOR | L1: STATUS | M1: OBS.
A2: 46094 | B2: =LOWER(TEXT(A2,"dddd")) -> sexta-feira | C2: MANHÃ | D2: 0.3125 | E2: 0.35416667 | F2: Estúdio 01 | G2: FLAVILTON DA SILVA MOURAO | H2: BIOLOGIA | I2: EM 1 TI | J2: seduc-pi1 | K2: Hamanda Soares | L2: OK | M2: TRANSMISSÃO
A3: 46094 | B3: =LOWER(TEXT(A3,"dddd")) -> sexta-feira | C3: MANHÃ | D3: 0.35416667 | E3: 0.39583333 | F3: Estúdio 01 | G3: FLAVILTON DA SILVA MOURAO | H3: BIOLOGIA | I3: EM 1 TI | J3: seduc-pi1 | K3: Hamanda Soares | L3: OK | M3: TRANSMISSÃO
A4: 46094 | B4: =LOWER(TEXT(A4,"dddd")) -> sexta-feira | C4: MANHÃ | D4: 0.40972222 | E4: 0.45138889 | F4: Estúdio 01 | G4: FLAVILTON DA SILVA MOURAO | H4: QUÍMICA | I4: EM 1 TI | J4: seduc-pi1 | K4: Erica Ramos | L4: OK | M4: TRANSMISSÃO
A5: 46094 | B5: =LOWER(TEXT(A5,"dddd")) -> sexta-feira | C5: MANHÃ | D5: 0.45138889 | E5: 0.49305556 | F5: Estúdio 01 | G5: FLAVILTON DA SILVA MOURAO | H5: QUÍMICA | I5: EM 1 TI | J5: seduc-pi1 | K5: Erica Ramos | L5: OK | M5: TRANSMISSÃO
A6: 46094 | B6: =LOWER(TEXT(A6,"dddd")) -> sexta-feira | C6: TARDE | D6: 0.53472222 | E6: 0.57638889
A7: 46094 | B7: =LOWER(TEXT(A7,"dddd")) -> sexta-feira | C7: TARDE | D7: 0.57638889 | E7: 0.61805556
A8: 46094 | B8: =LOWER(TEXT(A8,"dddd")) -> sexta-feira | C8: TARDE | D8: 0.63194444 | E8: 16.:10
A9: 46094 | B9: =LOWER(TEXT(A9,"dddd")) -> sexta-feira | C9: TARDE | D9: 0.67361111 | E9: 0.71527778
A10: 46094 | B10: =LOWER(TEXT(A10,"dddd")) -> sexta-feira | C10: MANHÃ | D10: 0.3125 | E10: 0.35416667 | F10: Estúdio 02 | G10: RENAN MESQUITA DE MELO SILVA | H10: BIOLOGIA | I10: EM 2 TIT | J10: seduc-pi2 | K10: Assis Gualter | L10: OK | M10: TRANSMISSÃO
A11: 46094 | B11: =LOWER(TEXT(A11,"dddd")) -> sexta-feira | C11: MANHÃ | D11: 0.35416667 | E11: 0.39583333 | F11: Estúdio 02 | G11: RENAN MESQUITA DE MELO SILVA | H11: BIOLOGIA | I11: EM 2 TIT | J11: seduc-pi2 | K11: Assis Gualter | L11: OK | M11: TRANSMISSÃO
A12: 46094 | B12: =LOWER(TEXT(A12,"dddd")) -> sexta-feira | C12: MANHÃ | D12: 0.40972222 | E12: 0.45138889 | F12: Estúdio 02 | G12: RENAN MESQUITA DE MELO SILVA | H12: LÍNGUA PORTUGUESA | I12: EM 2 TIT | J12: seduc-pi2 | K12: Hildalene Pinheiro | L12: OK | M12: TRANSMISSÃO
A13: 46094 | B13: =LOWER(TEXT(A13,"dddd")) -> sexta-feira | C13: MANHÃ | D13: 0.45138889 | E13: 0.49305556
A14: 46094 | B14: =LOWER(TEXT(A14,"dddd")) -> sexta-feira | C14: TARDE | D14: 0.53472222 | E14: 0.57638889
A15: 46094 | B15: =LOWER(TEXT(A15,"dddd")) -> sexta-feira | C15: TARDE | D15: 0.57638889 | E15: 0.61805556
A16: 46094 | B16: =LOWER(TEXT(A16,"dddd")) -> sexta-feira | C16: TARDE | D16: 0.63194444 | E16: 16.:10
A17: 46094 | B17: =LOWER(TEXT(A17,"dddd")) -> sexta-feira | C17: TARDE | D17: 0.67361111 | E17: 0.71527778
A18: 46094 | B18: =LOWER(TEXT(A18,"dddd")) -> sexta-feira | C18: MANHÃ | D18: 0.3125 | E18: 0.35416667 | F18: Estúdio 03 | G18: JOSÉ RIBAMAR FEITOSA DO NASCIMENTO JUNIOR | H18: CULTURA | I18: EM 3 TIT | J18: seduc-pi3 | K18: Keuri Campelo | L18: OK | M18: TRANSMISSÃO
A19: 46094 | B19: =LOWER(TEXT(A19,"dddd")) -> sexta-feira | C19: MANHÃ | D19: 0.35416667 | E19: 0.39583333 | F19: Estúdio 03 | G19: JOSÉ RIBAMAR FEITOSA DO NASCIMENTO JUNIOR | H19: CULTURA | I19: EM 3 TIT | J19: seduc-pi3 | K19: Keuri Campelo | L19: OK | M19: TRANSMISSÃO
A20: 46094 | B20: =LOWER(TEXT(A20,"dddd")) -> sexta-feira | C20: MANHÃ | D20: 0.40972222 | E20: 0.45138889 | F20: Estúdio 03 | G20: JOSÉ RIBAMAR FEITOSA DO NASCIMENTO JUNIOR | H20: ANÁLISE LINGUÍSTICA | I20: EM 3 TIT | J20: seduc-pi3 | K20: Alcides Fernandes | L20: OK | M20: TRANSMISSÃO
A21: 46094 | B21: =LOWER(TEXT(A21,"dddd")) -> sexta-feira | C21: MANHÃ | D21: 0.45138889 | E21: 0.49305556 | F21: Estúdio 03 | G21: JOSÉ RIBAMAR FEITOSA DO NASCIMENTO JUNIOR | H21: LITERATURA | I21: EM 3 TIT | J21: seduc-pi3 | K21: Hildalene Pinheiro | L21: OK | M21: TRANSMISSÃO
A22: 46094 | B22: =LOWER(TEXT(A22,"dddd")) -> sexta-feira | C22: TARDE | D22: 0.53472222 | E22: 0.57638889
A23: 46094 | B23: =LOWER(TEXT(A23,"dddd")) -> sexta-feira | C23: TARDE | D23: 0.57638889 | E23: 0.61805556
A24: 46094 | B24: =LOWER(TEXT(A24,"dddd")) -> sexta-feira | C24: TARDE | D24: 0.63194444 | E24: 16.:10
A25: 46094 | B25: =LOWER(TEXT(A25,"dddd")) -> sexta-feira | C25: TARDE | D25: 0.67361111 | E25: 0.71527778
A26: 46094 | B26: =LOWER(TEXT(A26,"dddd")) -> sexta-feira | C26: MANHÃ | D26: 0.29166667 | E26: 0.33333333 | F26: Estúdio 04 | G26: ECILMAR MONTEIRO DE BRITO SILVA | H26: QUÍMICA | I26: EM 3 MANHÃ | J26: seduc-pi4 | K26: Erica Ramos | L26: OK | M26: TRANSMISSÃO
A27: 46094 | B27: =LOWER(TEXT(A27,"dddd")) -> sexta-feira | C27: MANHÃ | D27: 0.33333333 | E27: 0.375 | F27: Estúdio 04 | G27: ECILMAR MONTEIRO DE BRITO SILVA | H27: QUÍMICA | I27: EM 3 MANHÃ | J27: seduc-pi4 | K27: Erica Ramos | L27: OK | M27: TRANSMISSÃO
A28: 46094 | B28: =LOWER(TEXT(A28,"dddd")) -> sexta-feira | C28: MANHÃ | D28: 0.375 | E28: 0.41666667 | F28: Estúdio 04 | G28: ECILMAR MONTEIRO DE BRITO SILVA | H28: GEOGRAFIA | I28: EM 3 MANHÃ | J28: seduc-pi4 | K28: Francisco Sousa | L28: OK | M28: TRANSMISSÃO
A29: 46094 | B29: =LOWER(TEXT(A29,"dddd")) -> sexta-feira | C29: MANHÃ | D29: 0.43055556 | E29: 0.47222222 | F29: Estúdio 04 | G29: ECILMAR MONTEIRO DE BRITO SILVA | H29: BIOLOGIA | I29: EM 3 MANHÃ | J29: seduc-pi4 | K29: Hamanda Soares | L29: OK | M29: TRANSMISSÃO
A30: 46094 | B30: =LOWER(TEXT(A30,"dddd")) -> sexta-feira | C30: MANHÃ | D30: 0.47222222 | E30: 0.51388889 | F30: Estúdio 04 | G30: ECILMAR MONTEIRO DE BRITO SILVA | H30: PROJETO DE VIDA | I30: EM 3 MANHÃ | J30: seduc-pi4 | K30: Hamanda Soares | L30: OK | M30: TRANSMISSÃO
A31: 46094 | B31: =LOWER(TEXT(A31,"dddd")) -> sexta-feira | C31: TARDE | D31: 0.54166667 | E31: 0.58333333 | F31: Estúdio 04 | G31: THIAGO DA CONCEICAO SOUSA | H31: LÍNGUA PORTUGUESA | I31: EM 3 TARDE | J31: seduc-pi4 | K31: Hildalene Pinheiro | L31: OK | M31: TRANSMISSÃO
A32: 46094 | B32: =LOWER(TEXT(A32,"dddd")) -> sexta-feira | C32: TARDE | D32: 0.58333333 | E32: 0.625 | F32: Estúdio 04 | G32: THIAGO DA CONCEICAO SOUSA | H32: QUÍMICA | I32: EM 3 TARDE | J32: seduc-pi4 | K32: Alcides Fernandes | L32: OK | M32: TRANSMISSÃO
A33: 46094 | B33: =LOWER(TEXT(A33,"dddd")) -> sexta-feira | C33: TARDE | D33: 0.625 | E33: 0.66666667 | F33: Estúdio 04 | G33: THIAGO DA CONCEICAO SOUSA | H33: QUÍMICA | I33: EM 3 TARDE | J33: seduc-pi4 | K33: Alcides Fernandes | L33: OK | M33: TRANSMISSÃO
A34: 46094 | B34: =LOWER(TEXT(A34,"dddd")) -> sexta-feira | C34: TARDE | D34: 0.68055556 | E34: 0.72222222 | F34: Estúdio 04 | G34: THIAGO DA CONCEICAO SOUSA | H34: ARTE | I34: EM 3 TARDE | J34: seduc-pi4 | K34: Adeildo Alves | L34: OK | M34: TRANSMISSÃO
A35: 46094 | B35: =LOWER(TEXT(A35,"dddd")) -> sexta-feira | C35: MANHÃ | D35: 0.29166667 | E35: 0.33333333 | F35: Estúdio 07 | G35: FELIPE CARVALHO COSTA | H35: CLUBE DE LEITURA | J35: seduc-pi7 | K35: Hildalene Pinheiro | L35: OK | M35: TRANSMISSÃO
A36: 46094 | B36: =LOWER(TEXT(A36,"dddd")) -> sexta-feira | C36: MANHÃ | D36: 0.33333333 | E36: 0.375 | F36: Estúdio 07 | G36: FELIPE CARVALHO COSTA | H36: CLUBE DE LEITURA | J36: seduc-pi4 | K36: Hildalene Pinheiro | L36: OK | M36: TRANSMISSÃO
A37: 46094 | B37: =LOWER(TEXT(A37,"dddd")) -> sexta-feira | C37: NOITE | D37: 0.75 | E37: 0.79166667 | F37: Estúdio 01 | G37: KHALIL SAREV LOPES VERA CRUZ | H37: QUÍMICA | I37: EJATEC TEC ADM MOD3 | J37: seduc-pi3 | K37: Alcides Fernandes | L37: OK | M37: TRANSMISSÃO
A38: 46094 | B38: =LOWER(TEXT(A38,"dddd")) -> sexta-feira | C38: NOITE | D38: 0.79166667 | E38: 0.83333333 | F38: Estúdio 01 | G38: KHALIL SAREV LOPES VERA CRUZ | H38: ETP LOGÍSTICA EMPRESARIAL | I38: EJATEC TEC ADM MOD3 | J38: seduc-pi3 | K38: Hugo Ferreira | L38: OK | M38: TRANSMISSÃO
A39: 46094 | B39: =LOWER(TEXT(A39,"dddd")) -> sexta-feira | C39: NOITE | D39: 0.83333333 | E39: 0.875 | F39: Estúdio 01 | G39: KHALIL SAREV LOPES VERA CRUZ | H39: FILOSOFIA | I39: EJATEC TEC ADM MOD3 | J39: seduc-pi3 | K39: Marciano Brito | L39: OK | M39: TRANSMISSÃO
A40: 46094 | B40: =LOWER(TEXT(A40,"dddd")) -> sexta-feira | C40: NOITE | D40: 0.875 | E40: 0.91666667 | F40: Estúdio 01 | G40: KHALIL SAREV LOPES VERA CRUZ | H40: ROTINAS EMPRESARIAIS E EMPREENDEDORISMO | I40: EJATEC TEC ADM MOD3 | J40: seduc-pi3 | K40: Assis Gualter | L40: OK | M40: TRANSMISSÃO
...

Sheet Seductec
A1: Solicitação | F1: Execução | I1: Status
A2: Data | B2: Turno | C2: Horário | D2: Professor | E2: Disciplina | F2: Professor | G2: Disciplina | H2: Qnt Aulas Gravadas

Sheet Modelo
A1: DATA | B1: DIA | C1: TURNO | D1: ESTÚDIO | E1: CANAL | F1: CURSO | G1: HORÁRIO | H1: DISCIPLINA | I1: PROFESSOR | J1: REGULAR | L1: Estúdio | M1: Sistema | N1: Programação
A2: 45324 | B2: sexta-feira | C2: Manhã | D2: Estúdio 01 | E2: Aula curinga | F2: Gravação | H2: \\192.168.10.14\gravacao_de_aulas_coringas\MANHA\02.FEVEREIRO\02\MATEMÁTICA | I2: Alexsandro Kesller Fonseca Miranda | J2: não | L2: Estúdio 01 | M2: =COUNTIF(Sistema!D:D,L2) -> 8 | N2: =COUNTIF(Programacao!F:F,L2) -> 8
A3: 45325 | B3: sábado | C3: FDS-Tarde | D3: Estúdio 08 | E3: Seductec | F3: Gravação SEDUCTEC | H3: Eficiência Energética | I3: Carla Mota | J3: não | L3: Estúdio 02 | M3: =COUNTIF(Sistema!D:D,L3) -> 7 | N3: =COUNTIF(Programacao!F:F,L3) -> 7
A4: 45330 | B4: quinta-feira | C4: Manhã | D4: Estúdio 04 | E4: Evento SEDUC | F4: TRANSMISSÃO | H4: \\192.168.11.14\gravacoes\SEMANA PRESENTE\07.02 | J4: não | L4: Estúdio 03 | M4: =COUNTIF(Sistema!D:D,L4) -> 8 | N4: =COUNTIF(Programacao!F:F,L4) -> 8
A5: 45388 | B5: sábado | C5: FDS-Manhã | D5: Estúdio 02 | E5: Evento SEDUC | F5: UAPI | H5: \\192.168.10.14\gravacoes\UAPI\UAPI 3\04 - ABRIL\06-04 | J5: não | L5: Estúdio 04 | M5: =COUNTIF(Sistema!D:D,L5) -> 13 | N5: =COUNTIF(Programacao!F:F,L5) -> 13
A6: 45417 | B6: domingo | C6: FDS-Manhã | D6: Estúdio 06 | E6: Evento SEDUC | F6: PRÉ-ENEM | H6: 4ª LIVE ENEM | SEDUC-PI | 05/05/2024 - YouTube ; \\192.168.10.14\gravacoes\ENEM\MAIO | J6: não | L6: Estúdio 05 | M6: =COUNTIF(Sistema!D:D,L6) -> 2 | N6: =COUNTIF(Programacao!F:F,L6) -> 2
D7: Transmissão Externa | L7: Estúdio 06 | M7: =COUNTIF(Sistema!D:D,L7) -> 4 | N7: =COUNTIF(Programacao!F:F,L7) -> 4
A8: Curso | L8: Estúdio 07 | M8: =COUNTIF(Sistema!D:D,L8) -> 6 | N8: =COUNTIF(Programacao!F:F,L8) -> 6
A9: 1ª SÉRIE INTEGRAL | L9: Estúdio 08 | M9: =COUNTIF(Sistema!D:D,L9) -> 0 | N9: =COUNTIF(Programacao!F:F,L9) -> 0
A10: 1ª SÉRIE - MANHÃ | L10: Estúdio 09 | M10: =COUNTIF(Sistema!D:D,L10) -> 4 | N10: =COUNTIF(Programacao!F:F,L10) -> 4
A11: 1ª SÉRIE - TARDE | L11: Transmissão Externa | M11: =COUNTIF(Sistema!D:D,Modelo!L11) -> 0 | N11: =COUNTIF(Programacao!F:F,L11) -> 0
A12: 1ª SÉRIE - NOITE | L12: Total | M12: =SUM(M2:M10) -> 52 | N12: =SUM(N2:N10) -> 52
A13: 2ª SÉRIE INTEGRAL
A14: 2ª SÉRIE - MANHÃ
A15: 2ª SÉRIE - TARDE
A16: 2ª SÉRIE - NOITE
A17: 3ª SÉRIE INTEGRAL
A18: 3ª SÉRIE - MANHÃ
A19: 3ª SÉRIE - TARDE
A20: 3ª SÉRIE - NOITE
A21: EJA - ETAPA VI
A22: EJA - ETAPA VII
A23: EJA ETAPA IV - Ensino Fundamental 6º E 7º Ano
A24: Gravação
... A26: TRANSMISSÃO
